WARNING  selenium.webdriver.common.selenium_manager:selenium_manager.py:127 The chromedriver version (125.0.6422.60) detected in PATH at C:\Users\dell\AppData\Local\Programs\Python\Python312\Scripts\chromedriver.exe might not be compatible with the detected chrome version (126.0.6478.63); currently, chromedriver 126.0.6478.63 is recommended for chrome 126.*, so it is advised to delete the driver in PATH and retry
WARNING  urllib3.connectionpool:connectionpool.py:871 Retrying (Retry(total=2, connect=None, read=None, redirect=None, status=None)) after connection broken by 'NewConnectionError('<urllib3.connection.HTTPConnection object at 0x00000230FBE9F170>: Failed to establish a new connection: [WinError 10061] No connection could be made because the target machine actively refused it')': /session/526cde3696014efaefeb3b743bfd7246
WARNING  urllib3.connectionpool:connectionpool.py:871 Retrying (Retry(total=1, connect=None, read=None, redirect=None, status=None)) after connection broken by 'NewConnectionError('<urllib3.connection.HTTPConnection object at 0x00000230FBE9DBE0>: Failed to establish a new connection: [WinError 10061] No connection could be made because the target machine actively refused it')': /session/526cde3696014efaefeb3b743bfd7246
WARNING  urllib3.connectionpool:connectionpool.py:871 Retrying (Retry(total=0, connect=None, read=None, redirect=None, status=None)) after connection broken by 'NewConnectionError('<urllib3.connection.HTTPConnection object at 0x00000230FBE9DFA0>: Failed to establish a new connection: [WinError 10061] No connection could be made because the target machine actively refused it')': /session/526cde3696014efaefeb3b743bfd7246