WARNING  selenium.webdriver.common.selenium_manager:selenium_manager.py:127 The chromedriver version (125.0.6422.60) detected in PATH at C:\Users\dell\AppData\Local\Programs\Python\Python312\Scripts\chromedriver.exe might not be compatible with the detected chrome version (126.0.6478.63); currently, chromedriver 126.0.6478.63 is recommended for chrome 126.*, so it is advised to delete the driver in PATH and retry
WARNING  urllib3.connectionpool:connectionpool.py:871 Retrying (Retry(total=2, connect=None, read=None, redirect=None, status=None)) after connection broken by 'NewConnectionError('<urllib3.connection.HTTPConnection object at 0x0000028D70D96810>: Failed to establish a new connection: [WinError 10061] No connection could be made because the target machine actively refused it')': /session/23f7a70fa1bf4a907b8ed5eac3606bc0
WARNING  urllib3.connectionpool:connectionpool.py:871 Retrying (Retry(total=1, connect=None, read=None, redirect=None, status=None)) after connection broken by 'NewConnectionError('<urllib3.connection.HTTPConnection object at 0x0000028D70D95010>: Failed to establish a new connection: [WinError 10061] No connection could be made because the target machine actively refused it')': /session/23f7a70fa1bf4a907b8ed5eac3606bc0
WARNING  urllib3.connectionpool:connectionpool.py:871 Retrying (Retry(total=0, connect=None, read=None, redirect=None, status=None)) after connection broken by 'NewConnectionError('<urllib3.connection.HTTPConnection object at 0x0000028D70CBBB60>: Failed to establish a new connection: [WinError 10061] No connection could be made because the target machine actively refused it')': /session/23f7a70fa1bf4a907b8ed5eac3606bc0